Workbook

Sheet HFCs EFs
B2: Singapore does not produce HFC, so this will be focused on consumption only.
B4: Source: Singapore Emissions Factor Registry
B5: Sub-Category | C5: Activity Name | D5: EF (kg CO2-eq per unit) | E5: Unit
B6: Hydrofluorocarbons (Hfcs) | C6: HFC-1234yf (CF3CF=CH2) | D6: 1 | E6: kg
B7: Hydrofluorocarbons (Hfcs) | C7: HFC-43-10mee (CF3CHFCHFCF2CF3) | D7: 1650 | E7: kg
B8: Hydrofluorocarbons (Hfcs) | C8: HFC-245cb (CF3CF2CH3) | D8: 4620 | E8: kg
B9: Hydrofluorocarbons (Hfcs) | C9: (E)-HFC-1225ye (CF3CF=CHF(E)) | D9: 1 | E9: kg
B10: Hydrofluorocarbons (Hfcs) | C10: (Z)-HFC-1234ze (CF3CH=CHF(Z)) | D10: 1 | E10: kg
B11: Hydrofluorocarbons (Hfcs) | C11: HFC-245fa (CHF2CH2CF3) | D11: 858 | E11: kg
B12: Hydrofluorocarbons (Hfcs) | C12: HFC-134 (CHF2CHF2) | D12: 1120 | E12: kg
B13: Hydrofluorocarbons (Hfcs) | C13: HFC-227ea (CF3CHFCF3) | D13: 3350 | E13: kg
B14: Hydrofluorocarbons (Hfcs) | C14: HFC-152 (CH2FCH2F) | D14: 16 | E14: kg
B15: Hydrofluorocarbons (Hfcs) | C15: HFC-32 (CH2F2) | D15: 677 | E15: kg
B16: Hydrofluorocarbons (Hfcs) | C16: HFC-143 (CH2FCHF2) | D16: 328 | E16: kg
B17: Hydrofluorocarbons (Hfcs) | C17: (Z)-HFC-1225ye (CF3CF=CHF(Z)) | D17: 1 | E17: kg
... B86: Refrigerants | C86: R-504 (48.2% HFC-32) | D86: 326.314 | E86: kg
B91: 1. Calculate Residual Emissions (During Use)
B92: Residual emissions are the ongoing, steady-state leakages that occur throughout the operational lifespan of refrigeration or air conditioning (RAC) equipment. [1, 2, 3, 4]
B93: The primary formula for bottom-up estimation is:
B94: Annual emissions = Total charge x annual leakage rage
B95: Total Charge: The total mass of the HFC inside the equipment.
B96: Annual Leakage Rate: The percentage of the charge that leaks per year. [1]
B98: 2. Calculate End-of-Life (EOL) Emissions
B99: End-of-life emissions represent the release of the remaining refrigerant when equipment is decommissioned or disposed of. [1, 2, 3, 4]
B100: The calculation follows this formula :
B101: EOL emissions = Initial charge x residual charge % x (1 - Recovery efficiency)
B102: Residual Charge %: The percentage of the total charge remaining in the system at the time of disposal.
B103: Recovery Efficiency: The fraction of the residual HFC that is actually captured and recovered (ranges from 0 to 1) . Any captured gas that is recycled or reclaimed does not count as an emission into the atmosphere. [1, 2, 3, 4, 5]
... B111: Source: GHG Protocol HFC Tool v1.0

Sheet Methane (New)
B6: Year | C6: Gas supply (TJ) | D6: Gas supply (TWh) | E6: CH4 emissions from gas (tonnes) | F6: Oil supply (TJ) | G6: Oil supply (TWh) | H6: CH4 emissions from oil (tonnes) | I6: Total oil and gas supply (TWh) | J6: Total CH4 emissions from oil and gas (tonnes) | K6: CH4 emissions intensity (t/TWh) | L6: Total CH4 emissions
B7: 2010 | I7: =D7+G7 -> 0 | J7: =E7+H7 -> 0 | K7: =J7/I7 -> #DIV/0! | L7: =G7+J7 -> 0
B8: 2011 | I8: =D8+G8 -> 0 | J8: =E8+H8 -> 0 | K8: =J8/I8 -> #DIV/0! | L8: =G8+J8 -> 0
B9: 2012 | I9: =D9+G9 -> 0 | J9: =E9+H9 -> 0 | K9: =J9/I9 -> #DIV/0! | L9: =G9+J9 -> 0
B10: 2013 | I10: =D10+G10 -> 0 | J10: =E10+H10 -> 0 | K10: =J10/I10 -> #DIV/0! | L10: =G10+J10 -> 0
B11: 2014 | I11: =D11+G11 -> 0 | J11: =E11+H11 -> 0 | K11: =J11/I11 -> #DIV/0! | L11: =G11+J11 -> 0
B12: 2015 | I12: =D12+G12 -> 0 | J12: =E12+H12 -> 0 | K12: =J12/I12 -> #DIV/0! | L12: =G12+J12 -> 0
B13: 2016 | I13: =D13+G13 -> 0 | J13: =E13+H13 -> 0 | K13: =J13/I13 -> #DIV/0! | L13: =G13+J13 -> 0
B14: 2017 | I14: =D14+G14 -> 0 | J14: =E14+H14 -> 0 | K14: =J14/I14 -> #DIV/0! | L14: =G14+J14 -> 0
B15: 2018 | I15: =D15+G15 -> 0 | J15: =E15+H15 -> 0 | K15: =J15/I15 -> #DIV/0! | L15: =G15+J15 -> 0
B16: 2019 | I16: =D16+G16 -> 0 | J16: =E16+H16 -> 0 | K16: =J16/I16 -> #DIV/0! | L16: =G16+J16 -> 0
B17: 2020 | I17: =D17+G17 -> 0 | J17: =E17+H17 -> 0 | K17: =J17/I17 -> #DIV/0! | L17: =G17+J17 -> 0
B18: 2021 | I18: =D18+G18 -> 0 | J18: =E18+H18 -> 0 | K18: =J18/I18 -> #DIV/0! | L18: =G18+J18 -> 0
... B47: 2050 | I47: =D47+G47 -> 0 | J47: =E47+H47 -> 0 | K47: =J47/I47 -> #DIV/0! | L47: =G47+J47 -> 0
B48: Cumulative 2020-2050 | I48: =D48+G48 -> 0 | J48: =E48+H48 -> 0 | K48: =J48/I48 -> #DIV/0! | L48: =G48+J48 -> 0

Sheet Methane
C2: UN energy-balance methodology defines supply as a balance of production + imports - exports - bunkers ± stock changes
C4: Gas supply (TJ): total natural gas supply as reported in EMA’s Natural Gas Balance, which is already in supply-balance form.
B7: Methane emissions from oil and gas | E7: Historical data
E8: Computed/forecasted data
C9: Source: EMA (Singapore Energy Statistics) | F9: Source: IEA | I9: Source: Singapore National Inventory Document (NID) 2024
B10: Year | C10: Gas supply (TJ) | D10: Gas supply (TWh) | E10: CH4 emissions from gas (tonnes) | F10: Oil supply (TJ) | G10: Oil supply (TWh) | H10: CH4 emissions from oil (tonnes) | I10: Upstream fugitive CH4 emissions from oil and gas (1000 tonnes) | J10: CH4 emissions from oil and gas (1000 tonnes) | K10: CH4 intensity (t/TWh) | L10: Upstream fugitive CH4 EF (kg CH4/kwh) | M10: Upstream fugitive CH4 EF (t/TWh) | N10: Total national CH4 emissions (1000 tonnes) | O10: CH4 emissions from Power sector (Mt CO2e)
B11: 2010 | C11: 302056.7 | D11: 83.904639 | E11: =Table29[[#This Row],[Gas supply (TWh)]]*M11 -> 186268.3 | F11: 735566 | G11: =F11*277.8*10^-6 -> 204.34023 | H11: =Table29[[#This Row],[Oil supply (TWh)]]*M11 -> 453635.32 | I11: 26.7 | J11: 15.847657 | K11: =(Table29[[#This Row],[Upstream fugitive CH4 emissions from oil and gas (1000 tonnes)]]*10^3)/(G11+D11) -> 92.629574 | L11: 0.00222 | M11: =L11*10^6 -> 2220 | N11: 123.26509 | O11: 0.0441
B12: 2011 | C12: 305083.7 | D12: 84.745472 | E12: =Table29[[#This Row],[Gas supply (TWh)]]*M12 -> 193219.68 | F12: 586680 | G12: =F12*277.8*10^-6 -> 162.9797 | H12: =Table29[[#This Row],[Oil supply (TWh)]]*M12 -> 371593.73 | I12: 35.4 | J12: 16.661519 | K12: =(Table29[[#This Row],[Upstream fugitive CH4 emissions from oil and gas (1000 tonnes)]]*10^3)/(G12+D12) -> 142.90029 | L12: 0.00228 | M12: =L12*10^6 -> 2280 | N12: 125.01747 | O12: 0.0456
B13: 2012 | C13: 330824.2 | D13: 91.895611 | E13: =Table29[[#This Row],[Gas supply (TWh)]]*M13 -> 200332.43 | F13: 740687 | G13: =F13*277.8*10^-6 -> 205.76285 | H13: =Table29[[#This Row],[Oil supply (TWh)]]*M13 -> 448563.01 | I13: 36.2 | J13: 16.811099 | K13: =(Table29[[#This Row],[Upstream fugitive CH4 emissions from oil and gas (1000 tonnes)]]*10^3)/(G13+D13) -> 121.6159 | L13: 0.00218 | M13: =L13*10^6 -> 2180 | N13: 126.25275 | O13: 0.0472
B14: 2013 | C14: 372461.9 | D14: 103.46164 | E14: =Table29[[#This Row],[Gas supply (TWh)]]*M14 -> 225546.37 | F14: 817646 | G14: =F14*277.8*10^-6 -> 227.14206 | H14: =Table29[[#This Row],[Oil supply (TWh)]]*M14 -> 495169.69 | I14: 32.14 | J14: 15.650585 | K14: =(Table29[[#This Row],[Upstream fugitive CH4 emissions from oil and gas (1000 tonnes)]]*10^3)/(G14+D14) -> 97.216094 | L14: 0.00218 | M14: =L14*10^6 -> 2180 | N14: 146.44053 | O14: 0.0524
B15: 2014 | C15: 390609.7 | D15: 108.50269 | E15: =Table29[[#This Row],[Gas supply (TWh)]]*M15 -> 238705.93 | F15: 744676 | G15: =F15*277.8*10^-6 -> 206.87099 | H15: =Table29[[#This Row],[Oil supply (TWh)]]*M15 -> 455116.18 | I15: 14.18 | J15: 14.52224 | K15: =(Table29[[#This Row],[Upstream fugitive CH4 emissions from oil and gas (1000 tonnes)]]*10^3)/(G15+D15) -> 44.962534 | L15: 0.0022 | M15: =L15*10^6 -> 2200 | N15: 152.44633 | O15: 0.0547
B16: 2015 | C16: 397532.5 | D16: 110.42569 | E16: =Table29[[#This Row],[Gas supply (TWh)]]*M16 -> 239623.76 | F16: 811498 | G16: =F16*277.8*10^-6 -> 225.43414 | H16: =Table29[[#This Row],[Oil supply (TWh)]]*M16 -> 489192.09 | I16: 14.24 | J16: 15.108963 | K16: =(Table29[[#This Row],[Upstream fugitive CH4 emissions from oil and gas (1000 tonnes)]]*10^3)/(G16+D16) -> 42.398639 | L16: 0.00217 | M16: =L16*10^6 -> 2170 | N16: 158.74875 | O16: 0.0545
B17: 2016 | C17: 407463.6 | D17: 113.18433 | E17: =Table29[[#This Row],[Gas supply (TWh)]]*M17 -> 244478.16 | F17: 863905 | G17: =F17*277.8*10^-6 -> 239.99281 | H17: =Table29[[#This Row],[Oil supply (TWh)]]*M17 -> 518384.47 | I17: 18.92 | J17: 15.48198 | K17: =(Table29[[#This Row],[Upstream fugitive CH4 emissions from oil and gas (1000 tonnes)]]*10^3)/(G17+D17) -> 53.570851 | L17: 0.00216 | M17: =L17*10^6 -> 2160 | N17: 150.85844 | O17: 0.0571
B18: 2017 | C18: 409714.1 | D18: 113.80947 | E18: =Table29[[#This Row],[Gas supply (TWh)]]*M18 -> 225342.75 | F18: 926115 | G18: =F18*277.8*10^-6 -> 257.27475 | H18: =Table29[[#This Row],[Oil supply (TWh)]]*M18 -> 509404 | I18: 22.79 | J18: 16.493213 | K18: =(Table29[[#This Row],[Upstream fugitive CH4 emissions from oil and gas (1000 tonnes)]]*10^3)/(G18+D18) -> 61.41463 | L18: 0.00198 | M18: =L18*10^6 -> 1980 | N18: 166.15277 | O18: 0.0572
B19: 2018 | C19: 418417.7 | D19: 116.22714 | E19: =Table29[[#This Row],[Gas supply (TWh)]]*M19 -> 247563.81 | F19: 918433 | G19: =F19*277.8*10^-6 -> 255.14069 | H19: =Table29[[#This Row],[Oil supply (TWh)]]*M19 -> 543449.66 | I19: 26.2 | J19: 16.334354 | K19: =(Table29[[#This Row],[Upstream fugitive CH4 emissions from oil and gas (1000 tonnes)]]*10^3)/(G19+D19) -> 70.55 | L19: 0.00213 | M19: =L19*10^6 -> 2130 | N19: 165.85596 | O19: 0.056
B20: 2019 | C20: 424642.1 | D20: 117.95614 | E20: =Table29[[#This Row],[Gas supply (TWh)]]*M20 -> 250067.01 | F20: 898047 | G20: =F20*277.8*10^-6 -> 249.47746 | H20: =Table29[[#This Row],[Oil supply (TWh)]]*M20 -> 528892.21 | I20: 36.45 | J20: 15.453571 | K20: =(Table29[[#This Row],[Upstream fugitive CH4 emissions from oil and gas (1000 tonnes)]]*10^3)/(G20+D20) -> 99.201598 | L20: 0.00212 | M20: =L20*10^6 -> 2120 | N20: 171.00021 | O20: 0.0577
B21: 2020 | C21: 429250.3 | D21: 119.23619 | E21: =Table29[[#This Row],[Gas supply (TWh)]]*M21 -> 252780.73 | F21: 885817 | G21: =F21*277.8*10^-6 -> 246.07996 | H21: =Table29[[#This Row],[Oil supply (TWh)]]*M21 -> 521689.52 | I21: 39.53 | J21: 13.248838 | K21: =(Table29[[#This Row],[Upstream fugitive CH4 emissions from oil and gas (1000 tonnes)]]*10^3)/(G21+D21) -> 108.20764 | L21: 0.00212 | M21: =L21*10^6 -> 2120 | N21: 162.91603 | O21: 0.0571
B22: 2021 | C22: 445730.3 | D22: 123.81397 | E22: =Table29[[#This Row],[Gas supply (TWh)]]*M22 -> 262485.62 | F22: 913908 | G22: =F22*277.8*10^-6 -> 253.88364 | H22: =Table29[[#This Row],[Oil supply (TWh)]]*M22 -> 538233.32 | I22: 41.43 | J22: 13.648687 | K22: =(Table29[[#This Row],[Upstream fugitive CH4 emissions from oil and gas (1000 tonnes)]]*10^3)/(G22+D22) -> 109.69092 | L22: 0.00212 | M22: =L22*10^6 -> 2120 | N22: 162.72994 | O22: 0.0577
B23: 2022 | C23: 440617.9 | D23: 122.39386 | E23: =Table29[[#This Row],[Gas supply (TWh)]]*M23 -> 259474.99 | F23: 918817 | G23: =F23*277.8*10^-6 -> 255.24736 | H23: =Table29[[#This Row],[Oil supply (TWh)]]*M23 -> 541124.41 | I23: 47.97 | J23: 14.826495 | K23: =(Table29[[#This Row],[Upstream fugitive CH4 emissions from oil and gas (1000 tonnes)]]*10^3)/(G23+D23) -> 127.02533 | L23: 0.00212 | M23: =L23*10^6 -> 2120 | N23: 160.02797 | O23: 0.0602
B24: 2023 | C24: 440444.3 | D24: 122.34564 | E24: =Table29[[#This Row],[Gas supply (TWh)]]*M24 -> 259372.75 | F24: 847955 | G24: =F24*277.8*10^-6 -> 235.5619 | H24: =Table29[[#This Row],[Oil supply (TWh)]]*M24 -> 499391.23 | J24: 14.559511 | K24: =(Table29[[#This Row],[Upstream fugitive CH4 emissions from oil and gas (1000 tonnes)]]*10^3)/(G24+D24) -> 0 | L24: 0.00212 | M24: =L24*10^6 -> 2120 | N24: 161.05769 | O24: 0.0617
B25: 2024 | C25: 453039.7 | D25: 125.84436 | E25: =Table29[[#This Row],[Gas supply (TWh)]]*M25 -> 266790.05 | F25: =AVERAGE(F21:F24) -> 891624.25 | G25: =F25*277.8*10^-6 -> 247.69322 | H25: =Table29[[#This Row],[Oil supply (TWh)]]*M25 -> 525109.62 | J25: 14.780217 | K25: =(Table29[[#This Row],[Upstream fugitive CH4 emissions from oil and gas (1000 tonnes)]]*10^3)/(G25+D25) -> 0 | L25: 0.00212 | M25: =L25*10^6 -> 2120 | N25: 168.61802 | O25: 0.0637
B26: 2025 | D26: =_xlfn.FORECAST.LINEAR(Table29[[#This Row],[Year]],D21:D25,B21:B25) -> 126.25121 | E26: =Table29[[#This Row],[Gas supply (TWh)]]*M26 -> 267652.56 | F26: =AVERAGE(F22:F25) -> 893076.06 | G26: =F26*277.8*10^-6 -> 248.09653 | H26: =Table29[[#This Row],[Oil supply (TWh)]]*M26 -> 525964.64 | J26: =(119*(Table29[[#This Row],[Gas supply (TWh)]]+Table29[[#This Row],[Oil supply (TWh)]]))*10^-3 -> 44.547381 | L26: 0.00212 | M26: =L26*10^6 -> 2120
B27: 2026 | D27: =_xlfn.FORECAST.LINEAR(Table29[[#This Row],[Year]],D22:D26,B22:B26) -> 126.6273 | E27: =Table29[[#This Row],[Gas supply (TWh)]]*M27 -> 268449.87 | F27: =AVERAGE(F23:F26) -> 887868.08 | G27: =F27*277.8*10^-6 -> 246.64975 | H27: =Table29[[#This Row],[Oil supply (TWh)]]*M27 -> 522897.47 | J27: =(M27*(Table29[[#This Row],[Gas supply (TWh)]]+Table29[[#This Row],[Oil supply (TWh)]]))*10^-3 -> 791.34735 | L27: 0.00212 | M27: =L27*10^6 -> 2120
B28: 2027 | D28: =_xlfn.FORECAST.LINEAR(Table29[[#This Row],[Year]],D23:D27,B23:B27) -> 128.4042 | E28: =Table29[[#This Row],[Gas supply (TWh)]]*M28 -> 272216.91 | F28: =AVERAGE(F24:F27) -> 880130.85 | G28: =F28*277.8*10^-6 -> 244.50035 | H28: =Table29[[#This Row],[Oil supply (TWh)]]*M28 -> 518340.74 | J28: =(M28*(Table29[[#This Row],[Gas supply (TWh)]]+Table29[[#This Row],[Oil supply (TWh)]]))*10^-3 -> 790.55766 | L28: 0.00212 | M28: =L28*10^6 -> 2120
B29: 2028 | D29: =_xlfn.FORECAST.LINEAR(Table29[[#This Row],[Year]],D24:D28,B24:B28) -> 129.76456 | E29: =Table29[[#This Row],[Gas supply (TWh)]]*M29 -> 275100.87 | F29: =AVERAGE(F25:F28) -> 888174.81 | G29: =F29*277.8*10^-6 -> 246.73496 | H29: =Table29[[#This Row],[Oil supply (TWh)]]*M29 -> 523078.12 | J29: =(M29*(Table29[[#This Row],[Gas supply (TWh)]]+Table29[[#This Row],[Oil supply (TWh)]]))*10^-3 -> 798.17899 | L29: 0.00212 | M29: =L29*10^6 -> 2120
B30: 2029 | D30: =_xlfn.FORECAST.LINEAR(Table29[[#This Row],[Year]],D25:D29,B25:B29) -> 130.37635 | E30: =Table29[[#This Row],[Gas supply (TWh)]]*M30 -> 276397.86 | F30: =AVERAGE(F26:F29) -> 887312.45 | G30: =F30*277.8*10^-6 -> 246.4954 | H30: =Table29[[#This Row],[Oil supply (TWh)]]*M30 -> 522570.24 | J30: =(M30*(Table29[[#This Row],[Gas supply (TWh)]]+Table29[[#This Row],[Oil supply (TWh)]]))*10^-3 -> 798.9681 | L30: 0.00212 | M30: =L30*10^6 -> 2120
B31: 2030 | D31: =_xlfn.FORECAST.LINEAR(Table29[[#This Row],[Year]],D26:D30,B26:B30) -> 131.70099 | E31: =Table29[[#This Row],[Gas supply (TWh)]]*M31 -> 279206.09 | F31: =AVERAGE(F27:F30) -> 885871.55 | G31: =F31*277.8*10^-6 -> 246.09512 | H31: =Table29[[#This Row],[Oil supply (TWh)]]*M31 -> 521721.64 | J31: =(M31*(Table29[[#This Row],[Gas supply (TWh)]]+Table29[[#This Row],[Oil supply (TWh)]]))*10^-3 -> 800.92774 | L31: 0.00212 | M31: =L31*10^6 -> 2120
B32: 2031 | D32: =_xlfn.FORECAST.LINEAR(Table29[[#This Row],[Year]],D27:D31,B27:B31) -> 133.01054 | E32: =Table29[[#This Row],[Gas supply (TWh)]]*M32 -> 281982.34 | F32: =AVERAGE(F28:F31) -> 885372.41 | G32: =F32*277.8*10^-6 -> 245.95646 | H32: =Table29[[#This Row],[Oil supply (TWh)]]*M32 -> 521427.69 | J32: =(M32*(Table29[[#This Row],[Gas supply (TWh)]]+Table29[[#This Row],[Oil supply (TWh)]]))*10^-3 -> 803.41002 | L32: 0.00212 | M32: =L32*10^6 -> 2120
B33: 2032 | D33: =_xlfn.FORECAST.LINEAR(Table29[[#This Row],[Year]],D28:D32,B28:B32) -> 133.99605 | E33: =Table29[[#This Row],[Gas supply (TWh)]]*M33 -> 284071.63 | F33: =AVERAGE(F29:F32) -> 886682.8 | G33: =F33*277.8*10^-6 -> 246.32048 | H33: =Table29[[#This Row],[Oil supply (TWh)]]*M33 -> 522199.42 | J33: =(M33*(Table29[[#This Row],[Gas supply (TWh)]]+Table29[[#This Row],[Oil supply (TWh)]]))*10^-3 -> 806.27106 | L33: 0.00212 | M33: =L33*10^6 -> 2120
B34: 2033 | D34: =_xlfn.FORECAST.LINEAR(Table29[[#This Row],[Year]],D29:D33,B29:B33) -> 135.09885 | E34: =Table29[[#This Row],[Gas supply (TWh)]]*M34 -> 286409.56 | F34: =AVERAGE(F30:F33) -> 886309.8 | G34: =F34*277.8*10^-6 -> 246.21686 | H34: =Table29[[#This Row],[Oil supply (TWh)]]*M34 -> 521979.75 | J34: =(M34*(Table29[[#This Row],[Gas supply (TWh)]]+Table29[[#This Row],[Oil supply (TWh)]]))*10^-3 -> 808.38931 | L34: 0.00212 | M34: =L34*10^6 -> 2120
B35: 2034 | D35: =_xlfn.FORECAST.LINEAR(Table29[[#This Row],[Year]],D30:D34,B30:B34) -> 136.35858 | E35: =Table29[[#This Row],[Gas supply (TWh)]]*M35 -> 289080.18 | F35: =AVERAGE(F31:F34) -> 886059.14 | G35: =F35*277.8*10^-6 -> 246.14723 | H35: =Table29[[#This Row],[Oil supply (TWh)]]*M35 -> 521832.13 | J35: =(M35*(Table29[[#This Row],[Gas supply (TWh)]]+Table29[[#This Row],[Oil supply (TWh)]]))*10^-3 -> 810.91231 | L35: 0.00212 | M35: =L35*10^6 -> 2120
B36: 2035 | D36: =_xlfn.FORECAST.LINEAR(Table29[[#This Row],[Year]],D31:D35,B31:B35) -> 137.45405 | E36: =Table29[[#This Row],[Gas supply (TWh)]]*M36 -> 291402.58 | F36: =AVERAGE(F32:F35) -> 886106.04 | G36: =F36*277.8*10^-6 -> 246.16026 | H36: =Table29[[#This Row],[Oil supply (TWh)]]*M36 -> 521859.75 | J36: =(M36*(Table29[[#This Row],[Gas supply (TWh)]]+Table29[[#This Row],[Oil supply (TWh)]]))*10^-3 -> 813.26233 | L36: 0.00212 | M36: =L36*10^6 -> 2120
B37: 2036 | D37: =_xlfn.FORECAST.LINEAR(Table29[[#This Row],[Year]],D32:D36,B32:B36) -> 138.55848 | E37: =Table29[[#This Row],[Gas supply (TWh)]]*M37 -> 293743.97 | F37: =AVERAGE(F33:F36) -> 886289.45 | G37: =F37*277.8*10^-6 -> 246.21121 | H37: =Table29[[#This Row],[Oil supply (TWh)]]*M37 -> 521967.76 | J37: =(M37*(Table29[[#This Row],[Gas supply (TWh)]]+Table29[[#This Row],[Oil supply (TWh)]]))*10^-3 -> 815.71173 | L37: 0.00212 | M37: =L37*10^6 -> 2120
B38: 2037 | D38: =_xlfn.FORECAST.LINEAR(Table29[[#This Row],[Year]],D33:D37,B33:B37) -> 139.73721 | E38: =Table29[[#This Row],[Gas supply (TWh)]]*M38 -> 296242.89 | F38: =AVERAGE(F34:F37) -> 886191.11 | G38: =F38*277.8*10^-6 -> 246.18389 | H38: =Table29[[#This Row],[Oil supply (TWh)]]*M38 -> 521909.85 | J38: =(M38*(Table29[[#This Row],[Gas supply (TWh)]]+Table29[[#This Row],[Oil supply (TWh)]]))*10^-3 -> 818.15274 | L38: 0.00212 | M38: =L38*10^6 -> 2120
... B51: 2050 | D51: =_xlfn.FORECAST.LINEAR(Table29[[#This Row],[Year]],D46:D50,B46:B50) -> 154.56353 | E51: =Table29[[#This Row],[Gas supply (TWh)]]*M51 -> 327674.69 | F51: =AVERAGE(F47:F50) -> 886190.36 | G51: =F51*277.8*10^-6 -> 246.18368 | H51: =Table29[[#This Row],[Oil supply (TWh)]]*M51 -> 521909.41 | J51: =(M51*(Table29[[#This Row],[Gas supply (TWh)]]+Table29[[#This Row],[Oil supply (TWh)]]))*10^-3 -> 849.5841 | L51: 0.00212 | M51: =L51*10^6 -> 2120
B52: Cumulative 2020-2050 | D52: =SUM(D21:D51) -> 4261.2964 | E52: =Table29[[#This Row],[Gas supply (TWh)]]*M52 -> 0 | F52: =SUM(F21:F51) -> 27504019 | G52: =SUM(G11:G51) -> 9875.0322 | H52: =Table29[[#This Row],[Oil supply (TWh)]]*M52 -> 0 | J52: =SUM(J21:J51) -> 20627.597 | M52: =L52*10^6 -> 0
J53: =(D52+G52)*K23*10^-3 -> 1795.6718
J54: =Table29[[#Totals],[CH4 emissions from oil and gas (1000 tonnes)]]*10^-3 -> 1.7956718 | K54: Mt
F56: Source: IEA
B57: Year | F57: Total oil supply (TJ) | G57: TWh | H57: CH4 emissions from oil | J57: CO2 emissions from oil (MtCO2e)
...

Sheet Vehicle Population
A1: year | B1: make | C1: fuel_type | D1: number
A2: 2005 | B2: ALFA ROMEO | D2: 914
A3: 2005 | B3: ASTON MARTIN | D3: 23
A4: 2005 | B4: AUDI | D4: 2025
A5: 2005 | B5: AUSTIN | D5: 137
A6: 2005 | B6: B.M.W. | D6: 15351
A7: 2005 | B7: BENTLEY | D7: 68
A8: 2005 | B8: CADILLAC | D8: 7
A9: 2005 | B9: CHEVROLET | D9: 3699
A10: 2005 | B10: CHRYSLER | D10: 422
A11: 2005 | B11: CITROEN | D11: 696
A12: 2005 | B12: DAEWOO | D12: 817
A13: 2005 | B13: DAIHATSU | D13: 2065
... A937: 2018 | B937: CITROEN | D937: 3776
A938: 2018 | B938: DAEWOO
A939: 2018 | B939: DAIHATSU | D939: 1046
A940: 2018 | B940: DAIMLER | D940: 20
A941: 2018 | B941: DATSUN | D941: 15
A942: 2018 | B942: DODGE
A943: 2018 | B943: DONGFENG | D943: 27
A944: 2018 | B944: FERRARI | D944: 643
A945: 2018 | B945: FIAT | D945: 701
A946: 2018 | B946: FORD | D946: 2731
A947: 2018 | B947: FOTON
A948: 2018 | B948: GEELY | D948: 55
A949: 2018 | B949: GOLDEN DRAGON
A950: 2018 | B950: HAFEI | D950: 26
A951: 2018 | B951: HOLDEN
A952: 2018 | B952: HONDA | D952: 96201
A953: 2018 | B953: HUMMER | D953: 23
A954: 2018 | B954: HYUNDAI | D954: 30445
A955: 2018 | B955: INFINITI | D955: 1228
A956: 2018 | B956: ISUZU
A957: 2018 | B957: JAGUAR | D957: 3817
A958: 2018 | B958: JEEP | D958: 248
A959: 2018 | B959: KIA | D959: 22138
A960: 2018 | B960: LAMBORGHINI | D960: 295
A961: 2018 | B961: LANCIA | D961: 8
A962: 2018 | B962: LAND ROVER | D962: 2808
A963: 2018 | B963: LOTUS | D963: 114
...

Sheet FLW Data
A3: 2020 (Population: 5.68 million) (UN Department of Economic and Social Affairs, Population Division, 2024)
J5: Source: World Bank Group
A6: Commodity Group | B6: Food Item | C6: EF (tCO2e/t food) | D6: Domestic production (t) | E6: AF | F6: FSC1 Input | G6: LF | H6: FSC1 Losses | I6: FSC1 Emissions | J6: Imports (t) | K6: Changes in stocks | L6: Exports | M6: FSC2 Input | N6: LF | O6: FSC2 Losses | P6: FSC2 Emissions | Q6: FSC3 Input | R6: LF | S6: FSC3 Losses | T6: FSC3 Emissions | U6: FSC4 Input | V6: LF | W6: FSC4 Losses | X6: FSC4 Emissions | Y6: FSC5 Input | Z6: LF | AA6: FSC5 Losses | AB6: FSC5 Emissions | AC6: Total Losses (t) | AD6: Total Emissions (t) | AE6: Total Emissions (Mt) | AG6: Net import emissions (t)
A7: Cereals | B7: Barley | C7: 0.75 | D7: 0 | E7: 0.36795184 | F7: =D7*E7 -> 0 | G7: 0.06 | H7: =F7*G7 -> 0 | I7: =H7*C7 -> 0 | J7: =240035.67*10^-3 -> 240.03567 | L7: =103030.39*10^-3 -> 103.03039 | M7: =(F7-H7)+(J7*E7)+(K7*E7)-(L7*E7) -> 50.411344 | N7: 0.0659 | O7: =M7*N7 -> 3.3221076 | P7: =O7*C7 -> 2.4915807 | Q7: =M7-O7 -> 47.089237 | R7: 0.07 | S7: =Q7*R7 -> 3.2962466 | T7: =S7*C7 -> 2.4721849 | U7: =Q7-S7 -> 43.79299 | V7: 0.0298 | W7: =U7*V7 -> 1.3050311 | X7: =W7*C7 -> 0.97877333 | Y7: =U7-W7 -> 42.487959 | Z7: 0.03 | AA7: =Y7*Z7 -> 1.2746388 | AB7: =AA7*C7 -> 0.95597908 | AC7: =H7+O7+S7+W7+AA7 -> 9.198024 | AD7: =I7+P7+T7+X7+AB7 -> 6.898518 | AE7: =AD7*10^-6 -> 6.898518e-06 | AG7: =(J7-L7)*C7 -> 102.75396
A8: Cereals | B8: Maize | C8: 1.73 | D8: 0 | E8: 0.31068539 | F8: =D8*E8 -> 0 | G8: 0.06 | H8: =F8*G8 -> 0 | I8: =H8*C8 -> 0 | J8: =(1885.31926142038+7552767.84207511+203216.71+13216042.41+1885.32)*10^-3 -> 20975.798 | L8: =0.001*(294433.82+738699.15+5340) -> 1038.473 | M8: =(F8-H8)+(J8*E8)+(K8*E8)-(L8*E8) -> 6194.2355 | N8: 0.0659 | O8: =M8*N8 -> 408.20012 | P8: =O8*C8 -> 706.1862 | Q8: =M8-O8 -> 5786.0354 | R8: 0.07 | S8: =Q8*R8 -> 405.02248 | T8: =S8*C8 -> 700.68888 | U8: =Q8-S8 -> 5381.0129 | V8: 0.0298 | W8: =U8*V8 -> 160.35418 | X8: =W8*C8 -> 277.41274 | Y8: =U8-W8 -> 5220.6587 | Z8: 0.03 | AA8: =Y8*Z8 -> 156.61976 | AB8: =AA8*C8 -> 270.95219 | AC8: =H8+O8+S8+W8+AA8 -> 1130.1965 | AD8: =I8+P8+T8+X8+AB8 -> 1955.24 | AE8: =AD8*10^-6 -> 0.00195524 | AG8: =(J8-L8)*C8 -> 34491.572
A9: Cereals | B9: Millet | C9: 0.93 | D9: 0 | E9: 0.93365991 | F9: =D9*E9 -> 0 | G9: 0.06 | H9: =F9*G9 -> 0 | I9: =H9*C9 -> 0 | J9: =249156.883219859*10^-3 -> 249.15688 | L9: =0.001*14460 -> 14.46 | M9: =(F9-H9)+(J9*E9)+(K9*E9)-(L9*E9) -> 219.12707 | N9: 0.0659 | O9: =M9*N9 -> 14.440474 | P9: =O9*C9 -> 13.429641 | Q9: =M9-O9 -> 204.6866 | R9: 0.07 | S9: =Q9*R9 -> 14.328062 | T9: =S9*C9 -> 13.325098 | U9: =Q9-S9 -> 190.35854 | V9: 0.0298 | W9: =U9*V9 -> 5.6726844 | X9: =W9*C9 -> 5.2755965 | Y9: =U9-W9 -> 184.68585 | Z9: 0.03 | AA9: =Y9*Z9 -> 5.5405755 | AB9: =AA9*C9 -> 5.1527353 | AC9: =H9+O9+S9+W9+AA9 -> 39.981796 | AD9: =I9+P9+T9+X9+AB9 -> 37.18307 | AE9: =AD9*10^-6 -> 3.718307e-05 | AG9: =(J9-L9)*C9 -> 218.2681
A10: Cereals | B10: Oats | C10: 0.93 | D10: 0 | E10: 0.83510638 | F10: =D10*E10 -> 0 | G10: 0.06 | H10: =F10*G10 -> 0 | I10: =H10*C10 -> 0 | J10: =10^-3*(2097688.5+671067.17+174766.56) -> 2943.5222 | L10: =0.001*(80764.38+176109.23+8010) -> 264.88361 | M10: =(F10-H10)+(J10*E10)+(K10*E10)-(L10*E10) -> 2236.9482 | N10: 0.0659 | O10: =M10*N10 -> 147.41489 | P10: =O10*C10 -> 137.09584 | Q10: =M10-O10 -> 2089.5333 | R10: 0.07 | S10: =Q10*R10 -> 146.26733 | T10: =S10*C10 -> 136.02862 | U10: =Q10-S10 -> 1943.266 | V10: 0.0298 | W10: =U10*V10 -> 57.909326 | X10: =W10*C10 -> 53.855674 | Y10: =U10-W10 -> 1885.3567 | Z10: 0.03 | AA10: =Y10*Z10 -> 56.5607 | AB10: =AA10*C10 -> 52.601451 | AC10: =H10+O10+S10+W10+AA10 -> 408.15225 | AD10: =I10+P10+T10+X10+AB10 -> 379.58159 | AE10: =AD10*10^-6 -> 0.00037958159 | AG10: =(J10-L10)*C10 -> 2491.1339
A11: Cereals | B11: Rice | C11: 1.91 | D11: 0 | E11: 0.6453202 | F11: =D11*E11 -> 0 | G11: 0.06 | H11: =F11*G11 -> 0 | I11: =H11*C11 -> 0 | J11: =10^-3*(400+9610062.89+13859330+372947700) -> 396417.49 | L11: =0.001*(1200+36211.89+100361020+9.42) -> 100398.44 | M11: =(F11-H11)+(J11*E11)+(K11*E11)-(L11*E11) -> 191027.07 | N11: 0.0659 | O11: =M11*N11 -> 12588.684 | P11: =O11*C11 -> 24044.387 | Q11: =M11-O11 -> 178438.39 | R11: 0.07 | S11: =Q11*R11 -> 12490.687 | T11: =S11*C11 -> 23857.213 | U11: =Q11-S11 -> 165947.7 | V11: 0.0298 | W11: =U11*V11 -> 4945.2415 | X11: =W11*C11 -> 9445.4113 | Y11: =U11-W11 -> 161002.46 | Z11: 0.03 | AA11: =Y11*Z11 -> 4830.0738 | AB11: =AA11*C11 -> 9225.441 | AC11: =H11+O11+S11+W11+AA11 -> 34854.687 | AD11: =I11+P11+T11+X11+AB11 -> 66572.451 | AE11: =AD11*10^-6 -> 0.066572451 | AG11: =(J11-L11)*C11 -> 565396.39
A12: Cereals | B12: Rye | C12: 0.7 | D12: 0 | E12: 0.83836158 | F12: =D12*E12 -> 0 | G12: 0.06 | H12: =F12*G12 -> 0 | I12: =H12*C12 -> 0 | J12: 1000 | L12: =50*10^-3 -> 0.05 | M12: =(F12-H12)+(J12*E12)+(K12*E12)-(L12*E12) -> 838.31966 | N12: 0.0659 | O12: =M12*N12 -> 55.245265 | P12: =O12*C12 -> 38.671686 | Q12: =M12-O12 -> 783.07439 | R12: 0.07 | S12: =Q12*R12 -> 54.815207 | T12: =S12*C12 -> 38.370645 | U12: =Q12-S12 -> 728.25919 | V12: 0.0298 | W12: =U12*V12 -> 21.702124 | X12: =W12*C12 -> 15.191487 | Y12: =U12-W12 -> 706.55706 | Z12: 0.03 | AA12: =Y12*Z12 -> 21.196712 | AB12: =AA12*C12 -> 14.837698 | AC12: =H12+O12+S12+W12+AA12 -> 152.95931 | AD12: =I12+P12+T12+X12+AB12 -> 107.07152 | AE12: =AD12*10^-6 -> 0.00010707152 | AG12: =(J12-L12)*C12 -> 699.965
A13: Cereals | B13: Sorghum | C13: 0.93 | D13: 0 | E13: 0.125 | F13: =D13*E13 -> 0 | G13: 0.06 | H13: =F13*G13 -> 0 | I13: =H13*C13 -> 0 | J13: =5087.02*10^-3 -> 5.08702 | L13: =0.001*3145.75 -> 3.14575 | M13: =(F13-H13)+(J13*E13)+(K13*E13)-(L13*E13) -> 0.24265875 | N13: 0.0659 | O13: =M13*N13 -> 0.015991212 | P13: =O13*C13 -> 0.014871827 | Q13: =M13-O13 -> 0.22666754 | R13: 0.07 | S13: =Q13*R13 -> 0.015866728 | T13: =S13*C13 -> 0.014756057 | U13: =Q13-S13 -> 0.21080081 | V13: 0.0298 | W13: =U13*V13 -> 0.0062818642 | X13: =W13*C13 -> 0.0058421337 | Y13: =U13-W13 -> 0.20451895 | Z13: 0.03 | AA13: =Y13*Z13 -> 0.0061355684 | AB13: =AA13*C13 -> 0.0057060786 | AC13: =H13+O13+S13+W13+AA13 -> 0.044275372 | AD13: =I13+P13+T13+X13+AB13 -> 0.041176096 | AE13: =AD13*10^-6 -> 4.1176096e-08 | AG13: =(J13-L13)*C13 -> 1.8053811
A14: Cereals | B14: Wheat | C14: 0.46 | D14: 0 | E14: 0.91825351 | F14: =D14*E14 -> 0 | G14: 0.06 | H14: =F14*G14 -> 0 | I14: =H14*C14 -> 0 | J14: =10^-3*(244381139.68+372272.27+760504.74) -> 245513.92 | L14: =0.001*(691.74+3320+6100) -> 10.11174 | M14: =(F14-H14)+(J14*E14)+(K14*E14)-(L14*E14) -> 225434.73 | N14: 0.0659 | O14: =M14*N14 -> 14856.149 | P14: =O14*C14 -> 6833.8284 | Q14: =M14-O14 -> 210578.58 | R14: 0.07 | S14: =Q14*R14 -> 14740.501 | T14: =S14*C14 -> 6780.6303 | U14: =Q14-S14 -> 195838.08 | V14: 0.0298 | W14: =U14*V14 -> 5835.9748 | X14: =W14*C14 -> 2684.5484 | Y14: =U14-W14 -> 190002.11 | Z14: 0.03 | AA14: =Y14*Z14 -> 5700.0632 | AB14: =AA14*C14 -> 2622.0291 | AC14: =H14+O14+S14+W14+AA14 -> 41132.687 | AD14: =I14+P14+T14+X14+AB14 -> 18921.036 | AE14: =AD14*10^-6 -> 0.018921036 | AG14: =(J14-L14)*C14 -> 112931.75
A15: Cereals | B15: Other Cereals | C15: 0.93 | D15: 0 | E15: 0.89187383 | F15: =D15*E15 -> 0 | G15: 0.06 | H15: =F15*G15 -> 0 | I15: =H15*C15 -> 0 | J15: =10^-3*(126298.3+240035.67+1362679.92+2598555.42+65650.42) -> 4393.2197 | L15: =0.001*(99296.66+1380.97+40572.8+117920) -> 259.17043 | M15: =(F15-H15)+(J15*E15)+(K15*E15)-(L15*E15) -> 3687.0504 | N15: 0.0659 | O15: =M15*N15 -> 242.97662 | P15: =O15*C15 -> 225.96826 | Q15: =M15-O15 -> 3444.0738 | R15: 0.07 | S15: =Q15*R15 -> 241.08516 | T15: =S15*C15 -> 224.2092 | U15: =Q15-S15 -> 3202.9886 | V15: 0.0298 | W15: =U15*V15 -> 95.44906 | X15: =W15*C15 -> 88.767626 | Y15: =U15-W15 -> 3107.5395 | Z15: 0.03 | AA15: =Y15*Z15 -> 93.226186 | AB15: =AA15*C15 -> 86.700353 | AC15: =H15+O15+S15+W15+AA15 -> 672.73703 | AD15: =I15+P15+T15+X15+AB15 -> 625.64544 | AE15: =AD15*10^-6 -> 0.00062564544 | AG15: =(J15-L15)*C15 -> 3844.6658
A16: Fruit & Vegetables | B16: Apples | C16: 0.34 | D16: 0 | E16: 1 | F16: =D16*E16 -> 0 | G16: 0.0871 | H16: =F16*G16 -> 0 | I16: =H16*C16 -> 0 | J16: =46221.1+9.343 -> 46230.443 | L16: =3959.84+0.01 -> 3959.85 | M16: =(F16-H16)+(J16*E16)+(K16*E16)-(L16*E16) -> 42270.593 | N16: 0.0987 | O16: =M16*N16 -> 4172.1075 | P16: =O16*C16 -> 1418.5166 | Q16: =M16-O16 -> 38098.485 | R16: 0.25 | S16: =Q16*R16 -> 9524.6214 | T16: =S16*C16 -> 3238.3713 | U16: =Q16-S16 -> 28573.864 | V16: 0.1296 | W16: =U16*V16 -> 3703.1728 | X16: =W16*C16 -> 1259.0787 | Y16: =U16-W16 -> 24870.691 | Z16: 0.1816 | AA16: =Y16*Z16 -> 4516.5175 | AB16: =AA16*C16 -> 1535.616 | AC16: =H16+O16+S16+W16+AA16 -> 21916.419 | AD16: =I16+P16+T16+X16+AB16 -> 7451.5825 | AE16: =AD16*10^-6 -> 0.0074515825 | AG16: =(J16-L16)*C16 -> 14372.002
A17: Fruit & Vegetables | B17: Bananas | C17: 0.45 | D17: 0 | E17: 0.99620668 | F17: =D17*E17 -> 0 | G17: 0.0871 | H17: =F17*G17 -> 0 | I17: =H17*C17 -> 0 | J17: =0.001*59095985.76 -> 59095.986 | L17: =28924.29*0.001 -> 28.92429 | M17: =(F17-H17)+(J17*E17)+(K17*E17)-(L17*E17) -> 58843.001 | N17: 0.0987 | O17: =M17*N17 -> 5807.8042 | P17: =O17*C17 -> 2613.5119 | Q17: =M17-O17 -> 53035.197 | R17: 0.25 | S17: =Q17*R17 -> 13258.799 | T17: =S17*C17 -> 5966.4597 | U17: =Q17-S17 -> 39776.398 | V17: 0.1296 | W17: =U17*V17 -> 5155.0212 | X17: =W17*C17 -> 2319.7595 | Y17: =U17-W17 -> 34621.377 | Z17: 0.1816 | AA17: =Y17*Z17 -> 6287.242 | AB17: =AA17*C17 -> 2829.2589 | AC17: =H17+O17+S17+W17+AA17 -> 30508.867 | AD17: =I17+P17+T17+X17+AB17 -> 13728.99 | AE17: =AD17*10^-6 -> 0.01372899 | AG17: =(J17-L17)*C17 -> 26580.178
A18: Fruit & Vegetables | B18: Citrus | C18: 0.23 | D18: 0 | E18: 1 | F18: =D18*E18 -> 0 | G18: 0.0871 | H18: =F18*G18 -> 0 | I18: =H18*C18 -> 0 | J18: =0.001*315533684.97 -> 315533.68 | L18: =16602893.48*0.001 -> 16602.893 | M18: =(F18-H18)+(J18*E18)+(K18*E18)-(L18*E18) -> 298930.79 | N18: 0.0987 | O18: =M18*N18 -> 29504.469 | P18: =O18*C18 -> 6786.0279 | Q18: =M18-O18 -> 269426.32 | R18: 0.25 | S18: =Q18*R18 -> 67356.581 | T18: =S18*C18 -> 15492.014 | U18: =Q18-S18 -> 202069.74 | V18: 0.1296 | W18: =U18*V18 -> 26188.239 | X18: =W18*C18 -> 6023.2949 | Y18: =U18-W18 -> 175881.5 | Z18: 0.1816 | AA18: =Y18*Z18 -> 31940.081 | AB18: =AA18*C18 -> 7346.2186 | AC18: =H18+O18+S18+W18+AA18 -> 154989.37 | AD18: =I18+P18+T18+X18+AB18 -> 35647.555 | AE18: =AD18*10^-6 -> 0.035647555 | AG18: =(J18-L18)*C18 -> 68754.082
A19: Fruit & Vegetables | B19: Grapes | C19: 0.62 | D19: 0 | E19: 1 | F19: =D19*E19 -> 0 | G19: 0.0871 | H19: =F19*G19 -> 0 | I19: =H19*C19 -> 0 | J19: =16131.2+1669.26 -> 17800.46 | L19: =1573.24+339.434 -> 1912.674 | M19: =(F19-H19)+(J19*E19)+(K19*E19)-(L19*E19) -> 15887.786 | N19: 0.0987 | O19: =M19*N19 -> 1568.1245 | P19: =O19*C19 -> 972.23718 | Q19: =M19-O19 -> 14319.662 | R19: 0.25 | S19: =Q19*R19 -> 3579.9154 | T19: =S19*C19 -> 2219.5475 | U19: =Q19-S19 -> 10739.746 | V19: 0.1296 | W19: =U19*V19 -> 1391.8711 | X19: =W19*C19 -> 862.96008 | Y19: =U19-W19 -> 9347.875 | Z19: 0.1816 | AA19: =Y19*Z19 -> 1697.5741 | AB19: =AA19*C19 -> 1052.4959 | AC19: =H19+O19+S19+W19+AA19 -> 8237.4851 | AD19: =I19+P19+T19+X19+AB19 -> 5107.2407 | AE19: =AD19*10^-6 -> 0.0051072407 | AG19: =(J19-L19)*C19 -> 9850.4273
A20: Fruit & Vegetables | B20: Other Fruit | C20: 0.84 | D20: 0 | E20: 1 | F20: =D20*E20 -> 0 | G20: 0.0871 | H20: =F20*G20 -> 0 | I20: =H20*C20 -> 0 | J20: =0.001*189998836.64 -> 189998.84 | L20: =66370685.4*0.001 -> 66370.685 | M20: =(F20-H20)+(J20*E20)+(K20*E20)-(L20*E20) -> 123628.15 | N20: 0.0987 | O20: =M20*N20 -> 12202.099 | P20: =O20*C20 -> 10249.763 | Q20: =M20-O20 -> 111426.05 | R20: 0.25 | S20: =Q20*R20 -> 27856.513 | T20: =S20*C20 -> 23399.471 | U20: =Q20-S20 -> 83569.54 | V20: 0.1296 | W20: =U20*V20 -> 10830.612 | X20: =W20*C20 -> 9097.7144 | Y20: =U20-W20 -> 72738.927 | Z20: 0.1816 | AA20: =Y20*Z20 -> 13209.389 | AB20: =AA20*C20 -> 11095.887 | AC20: =H20+O20+S20+W20+AA20 -> 64098.613 | AD20: =I20+P20+T20+X20+AB20 -> 53842.835 | AE20: =AD20*10^-6 -> 0.053842835 | AG20: =(J20-L20)*C20 -> 103847.65
A21: Fruit & Vegetables | B21: Vegetables | C21: 0.81 | D21: 22793 | E21: 0.99988602 | F21: =D21*E21 -> 22790.402 | G21: 0.0871 | H21: =F21*G21 -> 1985.044 | I21: =H21*C21 -> 1607.8857 | J21: =0.001*575260036.43 -> 575260.04 | L21: =0.001*25193075 -> 25193.075 | M21: =(F21-H21)+(J21*E21)+(K21*E21)-(L21*E21) -> 570809.62 | N21: 0.0987 | O21: =M21*N21 -> 56338.91 | P21: =O21*C21 -> 45634.517 | Q21: =M21-O21 -> 514470.72 | R21: 0.25 | S21: =Q21*R21 -> 128617.68 | T21: =S21*C21 -> 104180.32 | U21: =Q21-S21 -> 385853.04 | V21: 0.1296 | W21: =U21*V21 -> 50006.553 | X21: =W21*C21 -> 40505.308 | Y21: =U21-W21 -> 335846.48 | Z21: 0.1816 | AA21: =Y21*Z21 -> 60989.721 | AB21: =AA21*C21 -> 49401.674 | AC21: =H21+O21+S21+W21+AA21 -> 297937.91 | AD21: =I21+P21+T21+X21+AB21 -> 241329.71 | AE21: =AD21*10^-6 -> 0.24132971 | AG21: =(J21-L21)*C21 -> 445554.24
A22: Marine | B22: Fish & Seafood | C22: 5.29 | D22: 4567 | E22: 0.91631203 | F22: =D22*E22 -> 4184.797 | G22: 0.082 | H22: =F22*G22 -> 343.15336 | I22: =H22*C22 -> 1815.2813 | J22: =0.001*129826989.01 -> 129826.99 | L22: =17393428*0.001 -> 17393.428 | M22: =(F22-H22)+(J22*E22)+(K22*E22)-(L22*E22) -> 106865.87 | N22: 0.2547 | O22: =M22*N22 -> 27218.736 | P22: =O22*C22 -> 143987.12 | Q22: =M22-O22 -> 79647.131 | R22: 0.09 | S22: =Q22*R22 -> 7168.2418 | T22: =S22*C22 -> 37919.999 | U22: =Q22-S22 -> 72478.889 | V22: 0.1233 | W22: =U22*V22 -> 8936.6471 | X22: =W22*C22 -> 47274.863 | Y22: =U22-W22 -> 63542.242 | Z22: 0.02 | AA22: =Y22*Z22 -> 1270.8448 | AB22: =AA22*C22 -> 6722.7692 | AC22: =H22+O22+S22+W22+AA22 -> 44937.624 | AD22: =I22+P22+T22+X22+AB22 -> 237720.03 | AE22: =AD22*10^-6 -> 0.23772003 | AG22: =(J22-L22)*C22 -> 594773.54
A23: Meat | B23: Bovine | C23: 39.08 | D23: 0 | E23: 1 | F23: =D23*E23 -> 0 | G23: 0.1 | H23: =F23*G23 -> 0 | I23: =H23*C23 -> 0 | J23: =0.001*401024266 -> 401024.27 | L23: =0.001*171088883 -> 171088.88 | M23: =(F23-H23)+(J23*E23)+(K23*E23)-(L23*E23) -> 229935.38 | N23: 0.0021 | O23: =M23*N23 -> 482.8643 | P23: =O23*C23 -> 18870.337 | Q23: =M23-O23 -> 229452.52 | R23: 0.05 | S23: =Q23*R23 -> 11472.626 | T23: =S23*C23 -> 448350.22 | U23: =Q23-S23 -> 217979.89 | V23: 0.07 | W23: =U23*V23 -> 15258.592 | X23: =W23*C23 -> 596305.79 | Y23: =U23-W23 -> 202721.3 | Z23: 0.04 | AA23: =Y23*Z23 -> 8108.852 | AB23: =AA23*C23 -> 316893.94 | AC23: =H23+O23+S23+W23+AA23 -> 35322.935 | AD23: =I23+P23+T23+X23+AB23 -> 1380420.3 | AE23: =AD23*10^-6 -> 1.3804203 | AG23: =(J23-L23)*C23 -> 8985874.8
A24: Meat | B24: Mutton & Goat | C24: 15.71 | D24: 0 | E24: 1 | F24: =D24*E24 -> 0 | G24: 0.1 | H24: =F24*G24 -> 0 | I24: =H24*C24 -> 0 | J24: 15999.47 | L24: =0.001*1676525 -> 1676.525 | M24: =(F24-H24)+(J24*E24)+(K24*E24)-(L24*E24) -> 14322.945 | N24: 0.002 | O24: =M24*N24 -> 28.64589 | P24: =O24*C24 -> 450.02693 | Q24: =M24-O24 -> 14294.299 | R24: 0.05 | S24: =Q24*R24 -> 714.71496 | T24: =S24*C24 -> 11228.172 | U24: =Q24-S24 -> 13579.584 | V24: 0.07 | W24: =U24*V24 -> 950.57089 | X24: =W24*C24 -> 14933.469 | Y24: =U24-W24 -> 12629.013 | Z24: 0.04 | AA24: =Y24*Z24 -> 505.16053 | AB24: =AA24*C24 -> 7936.0719 | AC24: =H24+O24+S24+W24+AA24 -> 2199.0923 | AD24: =I24+P24+T24+X24+AB24 -> 34547.74 | AE24: =AD24*10^-6 -> 0.03454774 | AG24: =(J24-L24)*C24 -> 225013.47
A25: Meat | B25: Pig | C25: 6.92 | D25: 0 | E25: 1 | F25: =D25*E25 -> 0 | G25: 0.06 | H25: =F25*G25 -> 0 | I25: =H25*C25 -> 0 | J25: 107095.85 | L25: =0.001*7896757 -> 7896.757 | M25: =(F25-H25)+(J25*E25)+(K25*E25)-(L25*E25) -> 99199.097 | N25: 0.0047 | O25: =M25*N25 -> 466.23576 | P25: =O25*C25 -> 3226.3514 | Q25: =M25-O25 -> 98732.861 | R25: 0.05 | S25: =Q25*R25 -> 4936.6431 | T25: =S25*C25 -> 34161.57 | U25: =Q25-S25 -> 93796.218 | V25: 0.07 | W25: =U25*V25 -> 6565.7353 | X25: =W25*C25 -> 45434.888 | Y25: =U25-W25 -> 87230.483 | Z25: 0.04 | AA25: =Y25*Z25 -> 3489.2193 | AB25: =AA25*C25 -> 24145.398 | AC25: =H25+O25+S25+W25+AA25 -> 15457.833 | AD25: =I25+P25+T25+X25+AB25 -> 106968.21 | AE25: =AD25*10^-6 -> 0.10696821 | AG25: =(J25-L25)*C25 -> 686457.75
A26: Meat | B26: Poultry | C26: 4.68 | D26: 0 | E26: 0.9808929 | F26: =D26*E26 -> 0 | G26: 0.08 | H26: =F26*G26 -> 0 | I26: =H26*C26 -> 0 | J26: 195652.17 | L26: =0.001*29848933.06 -> 29848.933 | M26: =(F26-H26)+(J26*E26)+(K26*E26)-(L26*E26) -> 162635.22 | N26: 0.0097 | O26: =M26*N26 -> 1577.5616 | P26: =O26*C26 -> 7382.9884 | Q26: =M26-O26 -> 161057.66 | R26: 0.05 | S26: =Q26*R26 -> 8052.8828 | T26: =S26*C26 -> 37687.492 | U26: =Q26-S26 -> 153004.77 | V26: 0.07 | W26: =U26*V26 -> 10710.334 | X26: =W26*C26 -> 50124.364 | Y26: =U26-W26 -> 142294.44 | Z26: 0.04 | AA26: =Y26*Z26 -> 5691.7776 | AB26: =AA26*C26 -> 26637.519 | AC26: =H26+O26+S26+W26+AA26 -> 26032.556 | AD26: =I26+P26+T26+X26+AB26 -> 121832.36 | AE26: =AD26*10^-6 -> 0.12183236 | AG26: =(J26-L26)*C26 -> 775959.15
A27: Milk & Eggs | B27: Eggs | C27: 3.06 | D27: =616*60*10^-6 -> 0.03696 | E27: 0.90840606 | F27: =D27*E27 -> 0.033574688 | G27: 0.08 | H27: =F27*G27 -> 0.002685975 | I27: =H27*C27 -> 0.0082190836 | J27: =0.001*96281880.59 -> 96281.881 | L27: =0.001*2128779.68 -> 2128.7797 | M27: =(F27-H27)+(J27*E27)+(K27*E27)-(L27*E27) -> 85529.278 | N27: 0.0723 | O27: =M27*N27 -> 6183.7668 | P27: =O27*C27 -> 18922.326 | Q27: =M27-O27 -> 79345.511 | R27: 0.001 | S27: =Q27*R27 -> 79.345511 | T27: =S27*C27 -> 242.79726 | U27: =Q27-S27 -> 79266.166 | V27: 0.03 | W27: =U27*V27 -> 2377.985 | X27: =W27*C27 -> 7276.634 | Y27: =U27-W27 -> 76888.181 | Z27: 0.02 | AA27: =Y27*Z27 -> 1537.7636 | AB27: =AA27*C27 -> 4705.5567 | AC27: =H27+O27+S27+W27+AA27 -> 10178.864 | AD27: =I27+P27+T27+X27+AB27 -> 31147.323 | AE27: =AD27*10^-6 -> 0.031147323 | AG27: =(J27-L27)*C27 -> 288108.49
A28: Milk & Eggs | B28: Milk | C28: 2.31 | D28: 0 | E28: 0.83337698 | F28: =D28*E28 -> 0 | G28: 0.035 | H28: =F28*G28 -> 0 | I28: =H28*C28 -> 0 | J28: =237508883.05*10^-3 -> 237508.88 | L28: =0.001*12038141.5 -> 12038.141 | M28: =(F28-H28)+(J28*E28)+(K28*E28)-(L28*E28) -> 187902.13 | N28: 0.0468 | O28: =M28*N28 -> 8793.8195 | P28: =O28*C28 -> 20313.723 | Q28: =M28-O28 -> 179108.31 | R28: 0.02 | S28: =Q28*R28 -> 3582.1661 | T28: =S28*C28 -> 8274.8037 | U28: =Q28-S28 -> 175526.14 | V28: 0.1 | W28: =U28*V28 -> 17552.614 | X28: =W28*C28 -> 40546.538 | Y28: =U28-W28 -> 157973.53 | Z28: 0.01 | AA28: =Y28*Z28 -> 1579.7353 | AB28: =AA28*C28 -> 3649.1884 | AC28: =H28+O28+S28+W28+AA28 -> 31508.335 | AD28: =I28+P28+T28+X28+AB28 -> 72784.253 | AE28: =AD28*10^-6 -> 0.072784253 | AG28: =(J28-L28)*C28 -> 520837.41
A29: Oil crops & Pulses | B29: Oil crops | C29: 1.96 | D29: 0 | E29: 0.95656293 | F29: =D29*E29 -> 0 | G29: 0.07 | H29: =F29*G29 -> 0 | I29: =H29*C29 -> 0 | J29: =44428943*10^-3 -> 44428.943 | L29: =0.001*2643905.42 -> 2643.9054 | M29: =(F29-H29)+(J29*E29)+(K29*E29)-(L29*E29) -> 39970.018 | N29: 0.034 | O29: =M29*N29 -> 1358.9806 | P29: =O29*C29 -> 2663.602 | Q29: =M29-O29 -> 38611.037 | R29: 0.08 | S29: =Q29*R29 -> 3088.883 | T29: =S29*C29 -> 6054.2107 | U29: =Q29-S29 -> 35522.154 | V29: 0.02 | W29: =U29*V29 -> 710.44309 | X29: =W29*C29 -> 1392.4685 | Y29: =U29-W29 -> 34811.711 | Z29: 0.01 | AA29: =Y29*Z29 -> 348.11711 | AB29: =AA29*C29 -> 682.30954 | AC29: =H29+O29+S29+W29+AA29 -> 5506.4238 | AD29: =I29+P29+T29+X29+AB29 -> 10792.591 | AE29: =AD29*10^-6 -> 0.010792591 | AG29: =(J29-L29)*C29 -> 81898.674
A30: Oil crops & Pulses | B30: Pulses | C30: 0.34 | D30: 0 | E30: 0.78076999 | F30: =D30*E30 -> 0 | G30: 0.07 | H30: =F30*G30 -> 0 | I30: =H30*C30 -> 0 | J30: =21651816.59*10^-3 -> 21651.817 | L30: =0.001*1557977 -> 1557.977 | M30: =(F30-H30)+(J30*E30)+(K30*E30)-(L30*E30) -> 15688.667 | N30: 0.034 | O30: =M30*N30 -> 533.41468 | P30: =O30*C30 -> 181.36099 | Q30: =M30-O30 -> 15155.252 | R30: 0.08 | S30: =Q30*R30 -> 1212.4202 | T30: =S30*C30 -> 412.22286 | U30: =Q30-S30 -> 13942.832 | V30: 0.02 | W30: =U30*V30 -> 278.85664 | X30: =W30*C30 -> 94.811258 | Y30: =U30-W30 -> 13663.975 | Z30: 0.01 | AA30: =Y30*Z30 -> 136.63975 | AB30: =AA30*C30 -> 46.457517 | AC30: =H30+O30+S30+W30+AA30 -> 2161.3313 | AD30: =I30+P30+T30+X30+AB30 -> 734.85263 | AE30: =AD30*10^-6 -> 0.00073485263 | AG30: =(J30-L30)*C30 -> 6831.9055
A31: Roots & Tubers | B31: Starchy Roots | C31: 0.16 | D31: 0 | E31: 0.73231269 | F31: =D31*E31 -> 0 | G31: 0.0815 | H31: =F31*G31 -> 0 | I31: =H31*C31 -> 0 | J31: =10^-3*73754215 -> 73754.215 | L31: =0.001*1669222.74 -> 1669.2227 | M31: =(F31-H31)+(J31*E31)+(K31*E31)-(L31*E31) -> 52788.755 | N31: 0.1211 | O31: =M31*N31 -> 6392.7182 | P31: =O31*C31 -> 1022.8349 | Q31: =M31-O31 -> 46396.037 | R31: 0.1 | S31: =Q31*R31 -> 4639.6037 | T31: =S31*C31 -> 742.33658 | U31: =Q31-S31 -> 41756.433 | V31: 0.1078 | W31: =U31*V31 -> 4501.3435 | X31: =W31*C31 -> 720.21495 | Y31: =U31-W31 -> 37255.089 | Z31: 0.0388 | AA31: =Y31*Z31 -> 1445.4975 | AB31: =AA31*C31 -> 231.2796 | AC31: =H31+O31+S31+W31+AA31 -> 16979.163 | AD31: =I31+P31+T31+X31+AB31 -> 2716.666 | AE31: =AD31*10^-6 -> 0.002716666 | AG31: =(J31-L31)*C31 -> 11533.599
C32: =AVERAGE(C7:C31) -> 3.6828 | J32: =SUM(J7:J31) -> 3198882.2 | L32: =SUM(L7:L31) -> 464102.42 | AC32: =SUM(AC7:AC31) -> 846373.46 | AD32: =SUM(AD7:AD31) -> 2445377.4 | AE32: =AD32*10^-6 -> 2.4453774 | AG32: =SUM(AG7:AG31)*10^-6 -> 13.566426 | AH32: Total (Mt)
AC33: =AC32/5680000 -> 0.14900941 | AG33: =SUM(AG22:AG28)*10^-6 -> 12.077025 | AH33: Meat (Mt)
A36: 2050 (Population: 6.091 million) (UN Department of Economic and Social Affairs, Population Division, 2024)
J38: Source: Author's own calculations
A39: Commodity Group | B39: Food Item | C39: EF (tCO2e/t food) | D39: Domestic production (t) | E39: AF | F39: FSC1 Input | G39: LF | H39: FSC1 Losses | I39: FSC1 Emissions | J39: Imports (t) | K39: Changes in stocks | L39: Exports | M39: FSC2 Input | N39: LF | O39: FSC2 Losses | P39: FSC2 Emissions | Q39: FSC3 Input | R39: LF | S39: FSC3 Losses | T39: FSC3 Emissions | U39: FSC4 Input | V39: LF | W39: FSC4 Losses | X39: FSC4 Emissions | Y39: FSC5 Input | Z39: LF | AA39: FSC5 Losses | AB39: FSC5 Emissions | AC39: Total Losses | AD39: Total Emissions (t) | AE39: Total Emissions (Mt) | AG39: Net import emissions (t)
A40: Cereals | B40: Barley | C40: 0.75 | D40: 0 | E40: 0.36795184 | F40: =D40*E40 -> 0 | G40: 0.06 | H40: =F40*G40 -> 0 | I40: =H40*C40 -> 0 | J40: =J7/5.68*6.091 -> 257.40445 | L40: =L7/5.68*6.091 -> 110.48558 | M40: =(F40-H40)+(J40*E40)+(K40*E40)-(L40*E40) -> 54.059066 | N40: 0.0659 | O40: =M40*N40 -> 3.5624925 | P40: =O40*C40 -> 2.6718694 | Q40: =M40-O40 -> 50.496574 | R40: 0.07 | S40: =Q40*R40 -> 3.5347602 | T40: =S40*C40 -> 2.6510701 | U40: =Q40-S40 -> 46.961814 | V40: 0.0298 | W40: =U40*V40 -> 1.3994621 | X40: =W40*C40 -> 1.0495965 | Y40: =U40-W40 -> 45.562352 | Z40: 0.03 | AA40: =Y40*Z40 -> 1.3668706 | AB40: =AA40*C40 -> 1.0251529 | AC40: =H40+O40+S40+W40+AA40 -> 9.8635853 | AD40: =I40+P40+T40+X40+AB40 -> 7.3976889 | AE40: =AD40*10^-6 -> 7.3976889e-06 | AG40: =(J40-L40)*C40 -> 110.18915
A41: Cereals | B41: Maize | C41: 1.73 | D41: 0 | E41: 0.31068539 | F41: =D41*E41 -> 0 | G41: 0.06 | H41: =F41*G41 -> 0 | I41: =H41*C41 -> 0 | J41: =J8/5.68*6.091 -> 22493.589 | L41: =L8/5.68*6.091 -> 1113.616 | M41: =(F41-H41)+(J41*E41)+(K41*E41)-(L41*E41) -> 6642.4451 | N41: 0.0659 | O41: =M41*N41 -> 437.73713 | P41: =O41*C41 -> 757.28524 | Q41: =M41-O41 -> 6204.708 | R41: 0.07 | S41: =Q41*R41 -> 434.32956 | T41: =S41*C41 -> 751.39014 | U41: =Q41-S41 -> 5770.3784 | V41: 0.0298 | W41: =U41*V41 -> 171.95728 | X41: =W41*C41 -> 297.48609 | Y41: =U41-W41 -> 5598.4212 | Z41: 0.03 | AA41: =Y41*Z41 -> 167.95263 | AB41: =AA41*C41 -> 290.55806 | AC41: =H41+O41+S41+W41+AA41 -> 1211.9766 | AD41: =I41+P41+T41+X41+AB41 -> 2096.7195 | AE41: =AD41*10^-6 -> 0.0020967195 | AG41: =(J41-L41)*C41 -> 36987.353
A42: Cereals | B42: Millet | C42: 0.93 | D42: 0 | E42: 0.93365991 | F42: =D42*E42 -> 0 | G42: 0.06 | H42: =F42*G42 -> 0 | I42: =H42*C42 -> 0 | J42: =J9/5.68*6.091 -> 267.18566 | L42: =L9/5.68*6.091 -> 15.506313 | M42: =(F42-H42)+(J42*E42)+(K42*E42)-(L42*E42) -> 234.98292 | N42: 0.0659 | O42: =M42*N42 -> 15.485375 | P42: =O42*C42 -> 14.401398 | Q42: =M42-O42 -> 219.49755 | R42: 0.07 | S42: =Q42*R42 -> 15.364828 | T42: =S42*C42 -> 14.28929 | U42: =Q42-S42 -> 204.13272 | V42: 0.0298 | W42: =U42*V42 -> 6.083155 | X42: =W42*C42 -> 5.6573342 | Y42: =U42-W42 -> 198.04956 | Z42: 0.03 | AA42: =Y42*Z42 -> 5.9414869 | AB42: =AA42*C42 -> 5.5255828 | AC42: =H42+O42+S42+W42+AA42 -> 42.874845 | AD42: =I42+P42+T42+X42+AB42 -> 39.873606 | AE42: =AD42*10^-6 -> 3.9873606e-05 | AG42: =(J42-L42)*C42 -> 234.0618
A43: Cereals | B43: Oats | C43: 0.93 | D43: 0 | E43: 0.83510638 | F43: =D43*E43 -> 0 | G43: 0.06 | H43: =F43*G43 -> 0 | I43: =H43*C43 -> 0 | J43: =J10/5.68*6.091 -> 3156.513 | L43: =L10/5.68*6.091 -> 284.05036 | M43: =(F43-H43)+(J43*E43)+(K43*E43)-(L43*E43) -> 2398.8119 | N43: 0.0659 | O43: =M43*N43 -> 158.0817 | P43: =O43*C43 -> 147.01598 | Q43: =M43-O43 -> 2240.7302 | R43: 0.07 | S43: =Q43*R43 -> 156.85111 | T43: =S43*C43 -> 145.87154 | U43: =Q43-S43 -> 2083.8791 | V43: 0.0298 | W43: =U43*V43 -> 62.099596 | X43: =W43*C43 -> 57.752625 | Y43: =U43-W43 -> 2021.7795 | Z43: 0.03 | AA43: =Y43*Z43 -> 60.653384 | AB43: =AA43*C43 -> 56.407647 | AC43: =H43+O43+S43+W43+AA43 -> 437.6858 | AD43: =I43+P43+T43+X43+AB43 -> 407.04779 | AE43: =AD43*10^-6 -> 0.00040704779 | AG43: =(J43-L43)*C43 -> 2671.3903
A44: Cereals | B44: Rice | C44: 1.91 | D44: 0 | E44: 0.6453202 | F44: =D44*E44 -> 0 | G44: 0.06 | H44: =F44*G44 -> 0 | I44: =H44*C44 -> 0 | J44: =J11/5.68*6.091 -> 425101.93 | L44: =L11/5.68*6.091 -> 107663.19 | M44: =(F44-H44)+(J44*E44)+(K44*E44)-(L44*E44) -> 204849.63 | N44: 0.0659 | O44: =M44*N44 -> 13499.591 | P44: =O44*C44 -> 25784.218 | Q44: =M44-O44 -> 191350.04 | R44: 0.07 | S44: =Q44*R44 -> 13394.503 | T44: =S44*C44 -> 25583.5 | U44: =Q44-S44 -> 177955.54 | V44: 0.0298 | W44: =U44*V44 -> 5303.075 | X44: =W44*C44 -> 10128.873 | Y44: =U44-W44 -> 172652.46 | Z44: 0.03 | AA44: =Y44*Z44 -> 5179.5739 | AB44: =AA44*C44 -> 9892.9861 | AC44: =H44+O44+S44+W44+AA44 -> 37376.742 | AD44: =I44+P44+T44+X44+AB44 -> 71389.578 | AE44: =AD44*10^-6 -> 0.071389578 | AG44: =(J44-L44)*C44 -> 606307.99
A45: Cereals | B45: Rye | C45: 0.7 | D45: 0 | E45: 0.83836158 | F45: =D45*E45 -> 0 | G45: 0.06 | H45: =F45*G45 -> 0 | I45: =H45*C45 -> 0 | J45: =J12/5.68*6.091 -> 1072.3592 | L45: =L12/5.68*6.091 -> 0.053617958 | M45: =(F45-H45)+(J45*E45)+(K45*E45)-(L45*E45) -> 898.97976 | N45: 0.0659 | O45: =M45*N45 -> 59.242766 | P45: =O45*C45 -> 41.469936 | Q45: =M45-O45 -> 839.73699 | R45: 0.07 | S45: =Q45*R45 -> 58.78159 | T45: =S45*C45 -> 41.147113 | U45: =Q45-S45 -> 780.9554 | V45: 0.0298 | W45: =U45*V45 -> 23.272471 | X45: =W45*C45 -> 16.29073 | Y45: =U45-W45 -> 757.68293 | Z45: 0.03 | AA45: =Y45*Z45 -> 22.730488 | AB45: =AA45*C45 -> 15.911342 | AC45: =H45+O45+S45+W45+AA45 -> 164.02731 | AD45: =I45+P45+T45+X45+AB45 -> 114.81912 | AE45: =AD45*10^-6 -> 0.00011481912 | AG45: =(J45-L45)*C45 -> 750.61388
A46: Cereals | B46: Sorghum | C46: 0.93 | D46: 0 | E46: 0.125 | F46: =D46*E46 -> 0 | G46: 0.06 | H46: =F46*G46 -> 0 | I46: =H46*C46 -> 0 | J46: =J13/5.68*6.091 -> 5.4551125 | L46: =L13/5.68*6.091 -> 3.3733738 | M46: =(F46-H46)+(J46*E46)+(K46*E46)-(L46*E46) -> 0.26021733 | N46: 0.0659 | O46: =M46*N46 -> 0.017148322 | P46: =O46*C46 -> 0.01594794 | Q46: =M46-O46 -> 0.24306901 | R46: 0.07 | S46: =Q46*R46 -> 0.017014831 | T46: =S46*C46 -> 0.015823793 | U46: =Q46-S46 -> 0.22605418 | V46: 0.0298 | W46: =U46*V46 -> 0.0067364145 | X46: =W46*C46 -> 0.0062648655 | Y46: =U46-W46 -> 0.21931776 | Z46: 0.03 | AA46: =Y46*Z46 -> 0.0065795329 | AB46: =AA46*C46 -> 0.0061189656 | AC46: =H46+O46+S46+W46+AA46 -> 0.0474791 | AD46: =I46+P46+T46+X46+AB46 -> 0.044155563 | AE46: =AD46*10^-6 -> 4.4155563e-08 | AG46: =(J46-L46)*C46 -> 1.936017
...

Sheet FLW CF
A1: Food Loss & Waste
A3: Emission Factors & Allocation Factors | H3: Loss Factors
A4: Region | B4: Commodity group | C4: Commodity | D4: EF | E4: AF | H4: Scenario | I4: Region | J4: Commodity group | K4: Commodity | L4: FSC1 LF | M4: FSC2 LF | N4: FSC3 LF | O4: FSC4 LF | P4: FSC5 LF
A5: SSEA | B5: Cereals | C5: Barley | D5: 0.75 | E5: 0.36795184 | H5: Baseline | I5: SSEA | J5: Cereals | K5: N/A | L5: 6 | M5: 6.59 | N5: 7 | O5: 2.98 | P5: 3
A6: SSEA | B6: Cereals | C6: Maize | D6: 1.73 | E6: 0.31068539 | H6: Baseline | I6: SSEA | J6: Fruits & Vegetables | K6: N/A | L6: 8.71 | M6: 9.87 | N6: 25 | O6: 12.96 | P6: 18.16
A7: SSEA | B7: Cereals | C7: Millet | D7: 0.93 | E7: 0.93365991 | H7: Baseline | I7: SSEA | J7: Marine | K7: Fish & Seafood | L7: 8.2 | M7: 25.47 | N7: 9 | O7: 12.33 | P7: 2
A8: SSEA | B8: Cereals | C8: Oats | D8: 0.93 | E8: 0.83510638 | H8: Baseline | I8: SSEA | J8: Meat | K8: Bovine | L8: 10 | M8: 0.21 | N8: 5 | O8: 7 | P8: 4
A9: SSEA | B9: Cereals | C9: Rice | D9: 1.91 | E9: 0.6453202 | H9: Baseline | I9: SSEA | J9: Meat | K9: Mutton & Goat | L9: 10 | M9: 0.2 | N9: 5 | O9: 7 | P9: 4
A10: SSEA | B10: Cereals | C10: Rye | D10: 0.7 | E10: 0.83836158 | H10: Baseline | I10: SSEA | J10: Meat | K10: Pigmeat | L10: 6 | M10: 0.47 | N10: 5 | O10: 7 | P10: 4
A11: SSEA | B11: Cereals | C11: Sorghum | D11: 0.93 | E11: 0.125 | H11: Baseline | I11: SSEA | J11: Meat | K11: Poultry | L11: 8 | M11: 0.97 | N11: 5 | O11: 7 | P11: 4
A12: SSEA | B12: Cereals | C12: Wheat | D12: 0.46 | E12: 0.91825351 | H12: Baseline | I12: SSEA | J12: Milk & Eggs | K12: Eggs | L12: 8 | M12: 7.23 | N12: 0.1 | O12: 3 | P12: 2
A13: SSEA | B13: Cereals | C13: Other Cereals | D13: 0.93 | E13: 0.89187383 | H13: Baseline | I13: SSEA | J13: Milk & Eggs | K13: Milk | L13: 3.5 | M13: 4.68 | N13: 2 | O13: 10 | P13: 1
A14: SSEA | B14: Fruit & Vegetables | C14: Apples | D14: 0.34 | E14: 1 | H14: Baseline | I14: SSEA | J14: Oil crops & Pulses | K14: N/A | L14: 7 | M14: 3.4 | N14: 8 | O14: 2 | P14: 1
A15: SSEA | B15: Fruit & Vegetables | C15: Bananas | D15: 0.45 | E15: 0.99620668 | H15: Baseline | I15: SSEA | J15: Roots & Tubers | K15: Starchy Roots | L15: 8.15 | M15: 12.11 | N15: 10 | O15: 10.78 | P15: 3.88
A16: SSEA | B16: Fruit & Vegetables | C16: Citrus | D16: 0.23 | E16: 1
A17: SSEA | B17: Fruit & Vegetables | C17: Grapes | D17: 0.62 | E17: 1
A18: SSEA | B18: Fruit & Vegetables | C18: Other Fruit | D18: 0.84 | E18: 1
A19: SSEA | B19: Fruit & Vegetables | C19: Vegetables | D19: 0.81 | E19: 0.99988602
A20: SSEA | B20: Marine | C20: Fish & Seafood | D20: 5.29 | E20: 0.91631203
A21: SSEA | B21: Meat | C21: Bovine | D21: 39.08 | E21: 1
A22: SSEA | B22: Meat | C22: Mutton & Goat | D22: 15.71 | E22: 1
A23: SSEA | B23: Meat | C23: Pig | D23: 6.92 | E23: 1
A24: SSEA | B24: Meat | C24: Poultry | D24: 4.68 | E24: 0.9808929
A25: SSEA | B25: Milk & Eggs | C25: Eggs | D25: 3.06 | E25: 0.90840606
A26: SSEA | B26: Milk & Eggs | C26: Milk | D26: 2.31 | E26: 0.83337698
A27: SSEA | B27: Oil crops & Pulses | C27: Oil crops | D27: 1.96 | E27: 0.95656293
... A29: SSEA | B29: Roots & Tubers | C29: Starchy Roots | D29: 0.16 | E29: 0.73231269
A34: Food Supply Chain
A35: Scenario | B35: Year | C35: Region | D35: Commodity group | E35: Commodity | F35: FSC1 | G35: Import quantity | H35: Stock variation | I35: Export quantity | J35: Domestic Supply Quantity | K35: Feed | L35: Seed | M35: Other Uses (Non-food) | N35: AF | O35: FSC1 ID | P35: FSC2 ID | Q35: FSC3 ID | R35: FSC4 ID | S35: FSC5 ID
A36: 2018 | B36: 2018 | C36: SSEA | D36: Cereals | E36: Barley | F36: 4853 | G36: 4477 | H36: 416 | I36: 276 | J36: 8637 | K36: 5257 | L36: 202 | M36: 0 | N36: 0.36795184 | O36: 1785.6703 | P36: 3071.2277 | Q36: 2868.8338 | R36: 2668.0155 | S36: 2588.5086
A37: 2018 | B37: 2018 | C37: SSEA | D37: Cereals | E37: Maize | F37: 93280 | G37: 29441 | H37: 3840 | I37: 2948 | J37: 115934 | K37: 55631 | L37: 1327 | M37: 22957 | N37: 0.31068539 | O37: 28980.733 | P37: 34279.845 | Q37: 32020.804 | R37: 29779.347 | S37: 28891.923
A38: 2018 | B38: 2018 | C38: SSEA | D38: Cereals | E38: Millet | F38: 12525 | G38: 108 | H38: 507 | I38: 82 | J38: 12044 | K38: 519 | L38: 280 | M38: 0 | N38: 0.93365991 | O38: 11694.09 | P38: 10543.355 | Q38: 9848.5475 | R38: 9159.1492 | S38: 8886.2065
A39: 2018 | B39: 2018 | C39: SSEA | D39: Cereals | E39: Oats | F39: 0 | G39: 228 | H39: 5 | I39: 35 | J39: 188 | K39: 31 | L39: 0 | M39: 0 | N39: 0.83510638 | O39: 0 | P39: 157 | Q39: 146.6537 | R39: 136.38794 | S39: 132.32358
A40: 2018 | B40: 2018 | C40: SSEA | D40: Cereals | E40: Other cereals | F40: 505 | G40: 90 | H40: 22 | I40: 370 | J40: 203 | K40: 63 | L40: 8 | M40: 1 | N40: 0.6453202 | O40: 325.8867 | P40: 111.4468 | Q40: 104.10245 | R40: 96.815282 | S40: 93.930187
A41: 2018 | B41: 2018 | C41: SSEA | D41: Cereals | E41: Rice | F41: 470722 | G41: 13524 | H41: 30503 | I41: 51282 | J41: 402460 | K41: 23673 | L41: 9394 | M41: 31986 | N41: 0.83836158 | O41: 394635.24 | P41: 313729.72 | Q41: 293054.94 | R41: 272541.09 | S41: 264419.37
A42: 2018 | B42: 2018 | C42: SSEA | D42: Cereals | E42: Rye | F42: 0 | G42: 7 | H42: 0 | I42: 0 | J42: 8 | K42: 1 | L42: 0 | M42: 6 | N42: 0.125 | O42: 0 | P42: 0.875 | Q42: 0.8173375 | R42: 0.76012388 | S42: 0.73747218
A43: 2018 | B43: 2018 | C43: SSEA | D43: Cereals | E43: Sorghum | F43: 5205 | G43: 65 | H43: -44 | I43: 115 | J43: 5199 | K43: 257 | L43: 168 | M43: 0 | N43: 0.91825351 | O43: 4779.5095 | P43: 4487.2294 | Q43: 4191.521 | R43: 3898.1145 | S43: 3781.9507
A44: 2018 | B44: 2018 | C44: SSEA | D44: Cereals | E44: Wheat | F44: 146118 | G44: 37545 | H44: 1899 | I44: 5175 | J44: 176590 | K44: 10152 | L44: 5587 | M44: 3355 | N44: 0.89187383 | O44: 130318.82 | P44: 149675.98 | Q44: 139812.33 | R44: 130025.47 | S44: 126150.71
A45: 2018 | B45: 2018 | C45: SSEA | D45: Fruits & Vegetables | E45: Apples | F45: 5638 | G45: 1512 | H45: 836 | I45: 223 | J45: 6091 | K45: 0 | L45: 0 | M45: 0 | N45: 1 | O45: 5638 | P45: 5599.9302 | Q45: 5047.2171 | R45: 3785.4128 | S45: 3294.8233
A46: 2018 | B46: 2018 | C46: SSEA | D46: Fruits & Vegetables | E46: Bananas | F46: 50258 | G46: 458 | H46: 0 | I46: 4055 | J46: 46661 | K46: 177 | L46: 0 | M46: 0 | N46: 0.99620668 | O46: 50067.355 | P46: 42123.133 | Q46: 37965.58 | R46: 28474.185 | S46: 24783.931
...

Sheet Context
B3: Contextual elements to calculate present day shares
C5: Variable | D5: Year | E5: Unit | F5: Value | G5: Source | H5: Notes
C6: Singapore electricity generation | D6: 2020 | E6: TWh | F6: 53 | G6: EMA
C7: Singapore hydrogen demand | D7: - | E7: Mt | F7: 0 | G7: EMA
C8: Singapore passenger-km travelled by land (domestic only) | D8: 2020 | E8: Billion p-km
C9: Singapore passenger-km travelled by air | D9: 2020 | E9: Billion p-km | F9: =30045556650*0.000000001 -> 30.045557 | G9: UN Stats | H9: https://unstats.un.org/sdgs/dataportal/countryprofiles/sgp
C10: Useful energy for space cooling and water heating | D10: 2020 | E10: TWh
C11: Global households reliant on cookstoves | D11: 2020 | E11: Million | H11: Singapore is not reliant on cookstoves
C12: Steel production | D12: 2020 | E12: Tonnes | F12: 259495 | G12: Statbase | H12: https://statbase.org/data/sgp-steel-production/
C13: Cement production | D13: 2020 | E13: Tonnes | H13: Singapore only imports cement but not produce it
C14: Singapore cropland area | D14: 1991-2020 | E14: ha | F14: 100 | G14: UN FAO
C15: Singapore pasture area | D15: 1991-2020 | E15: ha | F15: 0 | H15: Singapore has no pasture
C16: Singapore forest area | D16: 1991-2020 | E16: ha | F16: 14730 | G16: UN FAO | H16: https://fra-data.fao.org/assessments/fra/latest/SGP/home/overview
B18: Contextual elements to calculate 2050 shares (scenario independent)
C20: Variable | D20: Year | E20: Unit | F20: Value | G20: Source | H20: Notes
C21: Cumulative HFC emissions | D21: 2050 | E21: MtCO2e
C22: Tropical cropland area | D22: 2050 | E22: ha
C23: Tropical pasture area | D23: 2050 | E23: ha | H23: Singapore has no pasture
C24: Tropical forest area | D24: 2050 | E24: ha | F24: 14730
C25: Calories from meat | D25: 2050 | E25: kcal/cap/day
C26: Food loss and waste | D26: 2050 | E26: Kt | F26: 650 | H26: Average from 2021-2024
C27: Hydrogen demand (low) | D27: 2050 | E27: Mt
C28: Hydrogen demand (high) | D28: 2050 | E28: Mt
B30: Contextual elements to calculate 2050 shares from baseline scenarios
C32: Variable | D32: Year | E32: Unit | F32: Values | G32: Source | H32: Notes
C33: Total electricity generation | D33: 2050 | E33: TWh | F33: 130 | G33: EMA
C34: Total passenger-km travelled by land (domestic only) | D34: 2050 | E34: Billion p-km | F34: 10000 | H34: Projected
C35: Total passenger-km travelled by air | D35: 2050 | E35: Billion p-km | F35: 0 | H35: Singapore does not rely on domestic flights for intra-city transport
C36: Total useful energy for space and water heating | D36: 2050 | E36: TWh
C37: Total demand for steel from all sources | D37: 2050 | E37: Mt
C38: Total demand for cement from all sources | D38: 2050 | E38: Mt
C39: Total cumulative methane emissions from oil and gas | D39: 2020-2050 | E39: MtCO2e
C40: Total GHG emissions from freight | D40: 2050 | E40: MtCO2e
B43: Sources
B44: 1 | C44: Ember, "Yearly Electricity Data" (2025).
B45: 2 | C45: IEA, “Global Hydrogen Review 2024” (2025).
B46: 3 | C46: Average of Global Calculator reference scenarios for 2020
B47: 4 | C47: ESMAP, “The State of Access to Modern Energy Cooking Services” (2020).
B48: 5 | C48: Author's analysis of ESA CCI and NASA MODIS datasets. See Materials and Methods for more details.
B49: 6 | C49: G. Dreyfus et al., “Assessment of Climate and Development Benefits of Efficient and Climate-Friendly Cooling” (2020).
...

Sheet Effort Summary
A1: # | B1: Sector | C1: Strategy | D1: Strategy Type | E1: Unit | F1: Current value (2020) | G1: Current share | H1: Source | I1: Wedge target | J1: Wedge target (high) | K1: Wedge target (low) | L1: Wedge share | M1: Wedge share (high) | N1: Wedge share (low) | O1: Scenario analysis: Wedge target (BAU) | P1: Scenario analysis: Wedge target (CPS) | Q1: Scenario analysis: Wedge target (NZS) | R1: Scenario analysis: Wedge share (BAU) | S1: Scenario analysis: Wedge share (CPS) | T1: Scenario analysis: Wedge share (NZS) | U1: Scenario independent: Wedge target (central) | V1: Scenario independent: Wedge target (high) | W1: Scenario independent: Wedge target (low)
A2: 1 | B2: Power | C2: Power BECCS with crops | D2: New | E2: TWh (output) | F2: 0 | G2: =F2/Context!$F$6 -> 0 | H2: Negligible | I2: =AVERAGE(O2:Q2) -> 1922.262 | J2: =MAX(O2:Q2) -> 1997.483 | K2: =MIN(O2:Q2) -> 1812.255 | L2: =AVERAGE(R2:T2) -> #REF! | M2: =MAX(R2:T2) -> #REF! | N2: =MIN(R2:T2) -> #REF! | O2: 1957.048 | P2: 1997.483 | Q2: 1812.255 | R2: =O2/#REF! -> #REF! | S2: =P2/#REF! -> #REF! | T2: =Q2/#REF! -> #REF! | U2: –– | V2: –– | W2: ––
A3: 2 | B3: Power | C3: Power BECCS with waste | D3: New | E3: TWh (output) | F3: 0 | G3: =F3/Context!$F$6 -> 0 | H3: Negligible | I3: =AVERAGE(O3:Q3) -> 1550.9783 | J3: =MAX(O3:Q3) -> 1600.022 | K3: =MIN(O3:Q3) -> 1478.94 | L3: =AVERAGE(R3:T3) -> #REF! | M3: =MAX(R3:T3) -> #REF! | N3: =MIN(R3:T3) -> #REF! | O3: 1573.973 | P3: 1600.022 | Q3: 1478.94 | R3: =O3/#REF! -> #REF! | S3: =P3/#REF! -> #REF! | T3: =Q3/#REF! -> #REF! | U3: –– | V3: –– | W3: ––
A4: 3 | B4: Power | C4: Retrofit coal plants with CCS | D4: Reduction | E4: TWh (output) | F4: 0 | G4: =F4/Context!$F$6 -> 0 | H4: Negligible | I4: =AVERAGE(O4:Q4) -> 2870.0089 | J4: =MAX(O4:Q4) -> 2892.9206 | K4: =MIN(O4:Q4) -> 2858.553 | L4: =AVERAGE(R4:T4) -> #REF! | M4: =MAX(R4:T4) -> #REF! | N4: =MIN(R4:T4) -> #REF! | O4: 2858.553 | P4: 2858.553 | Q4: 2892.9206 | R4: =O4/#REF! -> #REF! | S4: =P4/#REF! -> #REF! | T4: =Q4/#REF! -> #REF! | U4: –– | V4: –– | W4: ––
